2021-12-08 10:05:22 INFO routes.py home[line:15] Enter the home page
2021-12-08 10:05:22 INFO routes.py home[line:15] Enter the home page
2021-12-08 10:05:29 INFO routes.py register[line:24] User try to sign up
2021-12-08 10:22:37 INFO routes.py home[line:15] Enter the home page
2021-12-08 10:22:37 INFO routes.py home[line:15] Enter the home page
2021-12-08 10:22:45 ERROR app.py log_exception[line:1891] Exception on /sort/All [POST]
Traceback (most recent call last):
  File "G:\flaskProject\venv\lib\site-packages\flask\app.py", line 2447, in wsgi_app
    response = self.full_dispatch_request()
  File "G:\flaskProject\venv\lib\site-packages\flask\app.py", line 1952, in full_dispatch_request
    rv = self.handle_user_exception(e)
  File "G:\flaskProject\venv\lib\site-packages\flask\app.py", line 1821, in handle_user_exception
    reraise(exc_type, exc_value, tb)
  File "G:\flaskProject\venv\lib\site-packages\flask\_compat.py", line 39, in reraise
    raise value
  File "G:\flaskProject\venv\lib\site-packages\flask\app.py", line 1950, in full_dispatch_request
    rv = self.dispatch_request()
  File "G:\flaskProject\venv\lib\site-packages\flask\app.py", line 1936, in dispatch_request
    return self.view_functions[rule.endpoint](**req.view_args)
  File "G:\flaskProject\apps\routes.py", line 96, in soft_products
    else:
KeyError: 3
2021-12-08 10:29:21 INFO routes.py home[line:15] Enter the home page
2021-12-08 10:29:22 INFO routes.py home[line:15] Enter the home page
2021-12-08 10:49:43 INFO routes.py home[line:15] Enter the home page
2021-12-08 10:49:43 INFO routes.py home[line:15] Enter the home page
2021-12-08 10:51:25 INFO routes.py home[line:15] Enter the home page
2021-12-08 10:52:25 INFO routes.py home[line:15] Enter the home page
2021-12-08 10:52:25 INFO routes.py home[line:15] Enter the home page
2021-12-08 10:56:40 INFO routes.py home[line:15] Enter the home page
2021-12-08 10:58:48 INFO routes.py home[line:15] Enter the home page
2021-12-08 10:58:48 INFO routes.py home[line:15] Enter the home page
2021-12-08 11:26:27 INFO routes.py home[line:15] Enter the home page
2021-12-08 11:26:41 INFO routes.py login[line:64] Costumer login
2021-12-08 11:26:41 INFO routes.py home[line:15] Enter the home page
2021-12-08 11:26:44 INFO routes.py home[line:15] Enter the home page
2021-12-08 11:26:47 INFO routes.py category[line:106] category items
2021-12-08 11:26:49 INFO routes.py product[line:123] Successfully query
2021-12-08 11:26:49 INFO routes.py product[line:128] Successfully query
2021-12-08 11:26:52 INFO routes.py product[line:123] Successfully query
2021-12-08 11:26:52 INFO routes.py product[line:128] Successfully query
2021-12-08 11:26:52 INFO routes.py product[line:133] Costumer add products
2021-12-08 11:26:52 INFO routes.py product[line:143] Successfully added items to cart table
2021-12-08 11:26:52 INFO routes.py product[line:150] Adding to shopping cart successfully
2021-12-08 11:26:56 INFO routes.py product_collect[line:179] user add product into Favourite folder
2021-12-08 11:26:56 INFO routes.py home[line:15] Enter the home page
2021-12-08 11:33:06 INFO routes.py home[line:15] Enter the home page
2021-12-08 11:33:06 INFO routes.py home[line:15] Enter the home page
2021-12-08 11:33:09 INFO routes.py category[line:106] category items
2021-12-08 11:33:12 INFO routes.py product[line:123] Successfully query
2021-12-08 11:33:12 INFO routes.py product[line:128] Successfully query
2021-12-08 11:33:16 INFO routes.py product_collect[line:179] user add product into Favourite folder
2021-12-08 11:33:16 INFO routes.py product[line:123] Successfully query
2021-12-08 11:33:16 INFO routes.py product[line:128] Successfully query
2021-12-08 11:33:26 ERROR app.py log_exception[line:1891] Exception on /cart/update [POST]
Traceback (most recent call last):
  File "G:\flaskProject\venv\lib\site-packages\flask\app.py", line 2447, in wsgi_app
    response = self.full_dispatch_request()
  File "G:\flaskProject\venv\lib\site-packages\flask\app.py", line 1952, in full_dispatch_request
    rv = self.handle_user_exception(e)
  File "G:\flaskProject\venv\lib\site-packages\flask\app.py", line 1821, in handle_user_exception
    reraise(exc_type, exc_value, tb)
  File "G:\flaskProject\venv\lib\site-packages\flask\_compat.py", line 39, in reraise
    raise value
  File "G:\flaskProject\venv\lib\site-packages\flask\app.py", line 1950, in full_dispatch_request
    rv = self.dispatch_request()
  File "G:\flaskProject\venv\lib\site-packages\flask\app.py", line 1936, in dispatch_request
    return self.view_functions[rule.endpoint](**req.view_args)
  File "G:\flaskProject\apps\routes.py", line 348, in update_cart
    for i in session['cart']:
  File "G:\flaskProject\venv\lib\site-packages\werkzeug\local.py", line 378, in <lambda>
    __getitem__ = lambda x, i: x._get_current_object()[i]
  File "G:\flaskProject\venv\lib\site-packages\flask\sessions.py", line 84, in __getitem__
    return super(SecureCookieSession, self).__getitem__(key)
KeyError: 'cart
2021-12-08 11:33:49 INFO routes.py remove_from_cart[line:330] Successfully delete all product from cart table
2021-12-08 11:43:04 INFO routes.py category[line:106] category items
2021-12-08 11:43:06 INFO routes.py product[line:123] Successfully query
2021-12-08 11:43:06 INFO routes.py product[line:128] Successfully query
2021-12-08 11:43:09 INFO routes.py product[line:123] Successfully query
2021-12-08 11:43:09 INFO routes.py product[line:128] Successfully query
2021-12-08 11:43:09 INFO routes.py product[line:133] Costumer add products
2021-12-08 11:43:09 INFO routes.py product[line:143] Successfully added items to cart table
2021-12-08 11:43:09 INFO routes.py product[line:150] Adding to shopping cart successfully
2021-12-08 11:43:24 ERROR app.py log_exception[line:1891] Exception on /cart/update [POST]
Traceback (most recent call last):
  File "G:\flaskProject\venv\lib\site-packages\flask\app.py", line 2447, in wsgi_app
    response = self.full_dispatch_request()
  File "G:\flaskProject\venv\lib\site-packages\flask\app.py", line 1952, in full_dispatch_request
    rv = self.handle_user_exception(e)
  File "G:\flaskProject\venv\lib\site-packages\flask\app.py", line 1821, in handle_user_exception
    reraise(exc_type, exc_value, tb)
  File "G:\flaskProject\venv\lib\site-packages\flask\_compat.py", line 39, in reraise
    raise value
  File "G:\flaskProject\venv\lib\site-packages\flask\app.py", line 1950, in full_dispatch_request
    rv = self.dispatch_request()
  File "G:\flaskProject\venv\lib\site-packages\flask\app.py", line 1936, in dispatch_request
    return self.view_functions[rule.endpoint](**req.view_args)
  File "G:\flaskProject\apps\routes.py", line 348, in update_cart
    #     query = request.form.get('query')
  File "G:\flaskProject\venv\lib\site-packages\werkzeug\local.py", line 378, in <lambda>
    __getitem__ = lambda x, i: x._get_current_object()[i]
  File "G:\flaskProject\venv\lib\site-packages\flask\sessions.py", line 84, in __getitem__
    return super(SecureCookieSession, self).__getitem__(key)
KeyError: 'cart'
2021-12-08 11:48:24 INFO routes.py home[line:15] Enter the home page
2021-12-08 11:48:32 ERROR app.py log_exception[line:1891] Exception on /cart/update/19 [POST]
Traceback (most recent call last):
  File "G:\flaskProject\venv\lib\site-packages\flask\app.py", line 2447, in wsgi_app
    response = self.full_dispatch_request()
  File "G:\flaskProject\venv\lib\site-packages\flask\app.py", line 1952, in full_dispatch_request
    rv = self.handle_user_exception(e)
  File "G:\flaskProject\venv\lib\site-packages\flask\app.py", line 1821, in handle_user_exception
    reraise(exc_type, exc_value, tb)
  File "G:\flaskProject\venv\lib\site-packages\flask\_compat.py", line 39, in reraise
    raise value
  File "G:\flaskProject\venv\lib\site-packages\flask\app.py", line 1950, in full_dispatch_request
    rv = self.dispatch_request()
  File "G:\flaskProject\venv\lib\site-packages\flask\app.py", line 1936, in dispatch_request
    return self.view_functions[rule.endpoint](**req.view_args)
  File "G:\flaskProject\apps\routes.py", line 346, in update_cart
    quantity = int(request.form.get('quantity'))
TypeError: int() argument must be a string, a bytes-like object or a number, not 'NoneType'
2021-12-08 11:49:36 INFO routes.py home[line:15] Enter the home page
2021-12-08 11:49:40 ERROR app.py log_exception[line:1891] Exception on /cart [GET]
Traceback (most recent call last):
  File "G:\flaskProject\venv\lib\site-packages\flask\app.py", line 2447, in wsgi_app
    response = self.full_dispatch_request()
  File "G:\flaskProject\venv\lib\site-packages\flask\app.py", line 1952, in full_dispatch_request
    rv = self.handle_user_exception(e)
  File "G:\flaskProject\venv\lib\site-packages\flask\app.py", line 1821, in handle_user_exception
    reraise(exc_type, exc_value, tb)
  File "G:\flaskProject\venv\lib\site-packages\flask\_compat.py", line 39, in reraise
    raise value
  File "G:\flaskProject\venv\lib\site-packages\flask\app.py", line 1950, in full_dispatch_request
    rv = self.dispatch_request()
  File "G:\flaskProject\venv\lib\site-packages\flask\app.py", line 1936, in dispatch_request
    return self.view_functions[rule.endpoint](**req.view_args)
  File "G:\flaskProject\apps\routes.py", line 236, in cart
    return render_template('cart.html', title='Cart', total=total, total_price=total_price, shipping=shipping,
  File "G:\flaskProject\venv\lib\site-packages\flask\templating.py", line 137, in render_template
    return _render(
  File "G:\flaskProject\venv\lib\site-packages\flask\templating.py", line 120, in _render
    rv = template.render(context)
  File "G:\flaskProject\venv\lib\site-packages\jinja2\environment.py", line 1090, in render
    self.environment.handle_exception()
  File "G:\flaskProject\venv\lib\site-packages\jinja2\environment.py", line 832, in handle_exception
    reraise(*rewrite_traceback_stack(source=source))
  File "G:\flaskProject\venv\lib\site-packages\jinja2\_compat.py", line 28, in reraise
    raise value.with_traceback(tb)
  File "G:\flaskProject\apps\../templates\cart.html", line 1, in top-level template code
    {% extends "layout.html" %}
  File "G:\flaskProject\apps\../templates\layout.html", line 113, in top-level template code
    {% block content %}{% endblock %}
  File "G:\flaskProject\apps\../templates\cart.html", line 41, in block "content"
    <form id="update" method="POST" action="{{ url_for('update_cart') }}">
  File "G:\flaskProject\venv\lib\site-packages\flask\helpers.py", line 370, in url_for
    return appctx.app.handle_url_build_error(error, endpoint, values)
  File "G:\flaskProject\venv\lib\site-packages\flask\app.py", line 2216, in handle_url_build_error
    reraise(exc_type, exc_value, tb)
  File "G:\flaskProject\venv\lib\site-packages\flask\_compat.py", line 39, in reraise
    raise value
  File "G:\flaskProject\venv\lib\site-packages\flask\helpers.py", line 357, in url_for
    rv = url_adapter.build(
  File "G:\flaskProject\venv\lib\site-packages\werkzeug\routing.py", line 2020, in build
    raise BuildError(endpoint, values, method, self)
werkzeug.routing.BuildError: Could not build url for endpoint 'update_cart'. Did you forget to specify values ['product_id']?
2021-12-08 11:49:41 ERROR app.py log_exception[line:1891] Exception on /cart [GET]
Traceback (most recent call last):
  File "G:\flaskProject\venv\lib\site-packages\flask\app.py", line 2447, in wsgi_app
    response = self.full_dispatch_request()
  File "G:\flaskProject\venv\lib\site-packages\flask\app.py", line 1952, in full_dispatch_request
    rv = self.handle_user_exception(e)
  File "G:\flaskProject\venv\lib\site-packages\flask\app.py", line 1821, in handle_user_exception
    reraise(exc_type, exc_value, tb)
  File "G:\flaskProject\venv\lib\site-packages\flask\_compat.py", line 39, in reraise
    raise value
  File "G:\flaskProject\venv\lib\site-packages\flask\app.py", line 1950, in full_dispatch_request
    rv = self.dispatch_request()
  File "G:\flaskProject\venv\lib\site-packages\flask\app.py", line 1936, in dispatch_request
    return self.view_functions[rule.endpoint](**req.view_args)
  File "G:\flaskProject\apps\routes.py", line 236, in cart
    return render_template('cart.html', title='Cart', total=total, total_price=total_price, shipping=shipping,
  File "G:\flaskProject\venv\lib\site-packages\flask\templating.py", line 137, in render_template
    return _render(
  File "G:\flaskProject\venv\lib\site-packages\flask\templating.py", line 120, in _render
    rv = template.render(context)
  File "G:\flaskProject\venv\lib\site-packages\jinja2\environment.py", line 1090, in render
    self.environment.handle_exception()
  File "G:\flaskProject\venv\lib\site-packages\jinja2\environment.py", line 832, in handle_exception
    reraise(*rewrite_traceback_stack(source=source))
  File "G:\flaskProject\venv\lib\site-packages\jinja2\_compat.py", line 28, in reraise
    raise value.with_traceback(tb)
  File "G:\flaskProject\apps\../templates\cart.html", line 1, in top-level template code
    {% extends "layout.html" %}
  File "G:\flaskProject\apps\../templates\layout.html", line 113, in top-level template code
    {% block content %}{% endblock %}
  File "G:\flaskProject\apps\../templates\cart.html", line 41, in block "content"
    <form id="update" method="POST" action="{{ url_for('update_cart') }}">
  File "G:\flaskProject\venv\lib\site-packages\flask\helpers.py", line 370, in url_for
    return appctx.app.handle_url_build_error(error, endpoint, values)
  File "G:\flaskProject\venv\lib\site-packages\flask\app.py", line 2216, in handle_url_build_error
    reraise(exc_type, exc_value, tb)
  File "G:\flaskProject\venv\lib\site-packages\flask\_compat.py", line 39, in reraise
    raise value
  File "G:\flaskProject\venv\lib\site-packages\flask\helpers.py", line 357, in url_for
    rv = url_adapter.build(
  File "G:\flaskProject\venv\lib\site-packages\werkzeug\routing.py", line 2020, in build
    raise BuildError(endpoint, values, method, self)
werkzeug.routing.BuildError: Could not build url for endpoint 'update_cart'. Did you forget to specify values ['product_id']?
2021-12-08 11:50:26 INFO routes.py home[line:15] Enter the home page
2021-12-08 11:50:26 INFO routes.py home[line:15] Enter the home page
2021-12-08 11:50:33 ERROR app.py log_exception[line:1891] Exception on /cart/update/19 [POST]
Traceback (most recent call last):
  File "G:\flaskProject\venv\lib\site-packages\flask\app.py", line 2447, in wsgi_app
    response = self.full_dispatch_request()
  File "G:\flaskProject\venv\lib\site-packages\flask\app.py", line 1952, in full_dispatch_request
    rv = self.handle_user_exception(e)
  File "G:\flaskProject\venv\lib\site-packages\flask\app.py", line 1821, in handle_user_exception
    reraise(exc_type, exc_value, tb)
  File "G:\flaskProject\venv\lib\site-packages\flask\_compat.py", line 39, in reraise
    raise value
  File "G:\flaskProject\venv\lib\site-packages\flask\app.py", line 1950, in full_dispatch_request
    rv = self.dispatch_request()
  File "G:\flaskProject\venv\lib\site-packages\flask\app.py", line 1936, in dispatch_request
    return self.view_functions[rule.endpoint](**req.view_args)
  File "G:\flaskProject\apps\routes.py", line 346, in update_cart
    quantity = int(request.form.get('quantity'))
TypeError: int() argument must be a string, a bytes-like object or a number, not 'NoneType'
2021-12-08 11:50:37 ERROR app.py log_exception[line:1891] Exception on /cart/update/19 [POST]
Traceback (most recent call last):
  File "G:\flaskProject\venv\lib\site-packages\flask\app.py", line 2447, in wsgi_app
    response = self.full_dispatch_request()
  File "G:\flaskProject\venv\lib\site-packages\flask\app.py", line 1952, in full_dispatch_request
    rv = self.handle_user_exception(e)
  File "G:\flaskProject\venv\lib\site-packages\flask\app.py", line 1821, in handle_user_exception
    reraise(exc_type, exc_value, tb)
  File "G:\flaskProject\venv\lib\site-packages\flask\_compat.py", line 39, in reraise
    raise value
  File "G:\flaskProject\venv\lib\site-packages\flask\app.py", line 1950, in full_dispatch_request
    rv = self.dispatch_request()
  File "G:\flaskProject\venv\lib\site-packages\flask\app.py", line 1936, in dispatch_request
    return self.view_functions[rule.endpoint](**req.view_args)
  File "G:\flaskProject\apps\routes.py", line 346, in update_cart
    quantity = int(request.form.get('quantity'))
TypeError: int() argument must be a string, a bytes-like object or a number, not 'NoneType'
2021-12-08 11:52:39 INFO routes.py home[line:15] Enter the home page
2021-12-08 11:52:44 ERROR app.py log_exception[line:1891] Exception on /cart/update/19 [POST]
Traceback (most recent call last):
  File "G:\flaskProject\venv\lib\site-packages\flask\app.py", line 2447, in wsgi_app
    response = self.full_dispatch_request()
  File "G:\flaskProject\venv\lib\site-packages\flask\app.py", line 1952, in full_dispatch_request
    rv = self.handle_user_exception(e)
  File "G:\flaskProject\venv\lib\site-packages\flask\app.py", line 1821, in handle_user_exception
    reraise(exc_type, exc_value, tb)
  File "G:\flaskProject\venv\lib\site-packages\flask\_compat.py", line 39, in reraise
    raise value
  File "G:\flaskProject\venv\lib\site-packages\flask\app.py", line 1950, in full_dispatch_request
    rv = self.dispatch_request()
  File "G:\flaskProject\venv\lib\site-packages\flask\app.py", line 1936, in dispatch_request
    return self.view_functions[rule.endpoint](**req.view_args)
  File "G:\flaskProject\apps\routes.py", line 346, in update_cart
    quantity = int(request.form.get('quantity'))
TypeError: int() argument must be a string, a bytes-like object or a number, not 'NoneType'
2021-12-08 11:53:47 INFO routes.py home[line:15] Enter the home page
2021-12-08 11:53:53 ERROR app.py log_exception[line:1891] Exception on /cart/update/19 [POST]
Traceback (most recent call last):
  File "G:\flaskProject\venv\lib\site-packages\flask\app.py", line 2447, in wsgi_app
    response = self.full_dispatch_request()
  File "G:\flaskProject\venv\lib\site-packages\flask\app.py", line 1952, in full_dispatch_request
    rv = self.handle_user_exception(e)
  File "G:\flaskProject\venv\lib\site-packages\flask\app.py", line 1821, in handle_user_exception
    reraise(exc_type, exc_value, tb)
  File "G:\flaskProject\venv\lib\site-packages\flask\_compat.py", line 39, in reraise
    raise value
  File "G:\flaskProject\venv\lib\site-packages\flask\app.py", line 1950, in full_dispatch_request
    rv = self.dispatch_request()
  File "G:\flaskProject\venv\lib\site-packages\flask\app.py", line 1936, in dispatch_request
    return self.view_functions[rule.endpoint](**req.view_args)
  File "G:\flaskProject\apps\routes.py", line 346, in update_cart
    quantity = int(request.form.get('update_num'))
TypeError: int() argument must be a string, a bytes-like object or a number, not 'NoneType'
2021-12-08 11:56:17 INFO routes.py home[line:15] Enter the home page
2021-12-08 11:56:23 ERROR app.py log_exception[line:1891] Exception on /cart/update/19 [POST]
Traceback (most recent call last):
  File "G:\flaskProject\venv\lib\site-packages\flask\app.py", line 2447, in wsgi_app
    response = self.full_dispatch_request()
  File "G:\flaskProject\venv\lib\site-packages\flask\app.py", line 1952, in full_dispatch_request
    rv = self.handle_user_exception(e)
  File "G:\flaskProject\venv\lib\site-packages\flask\app.py", line 1821, in handle_user_exception
    reraise(exc_type, exc_value, tb)
  File "G:\flaskProject\venv\lib\site-packages\flask\_compat.py", line 39, in reraise
    raise value
  File "G:\flaskProject\venv\lib\site-packages\flask\app.py", line 1950, in full_dispatch_request
    rv = self.dispatch_request()
  File "G:\flaskProject\venv\lib\site-packages\flask\app.py", line 1936, in dispatch_request
    return self.view_functions[rule.endpoint](**req.view_args)
  File "G:\flaskProject\apps\routes.py", line 346, in update_cart
    quantity = int(request.form.get('update_num'))
TypeError: int() argument must be a string, a bytes-like object or a number, not 'NoneType'
2021-12-08 11:56:28 ERROR app.py log_exception[line:1891] Exception on /cart/update/19 [POST]
Traceback (most recent call last):
  File "G:\flaskProject\venv\lib\site-packages\flask\app.py", line 2447, in wsgi_app
    response = self.full_dispatch_request()
  File "G:\flaskProject\venv\lib\site-packages\flask\app.py", line 1952, in full_dispatch_request
    rv = self.handle_user_exception(e)
  File "G:\flaskProject\venv\lib\site-packages\flask\app.py", line 1821, in handle_user_exception
    reraise(exc_type, exc_value, tb)
  File "G:\flaskProject\venv\lib\site-packages\flask\_compat.py", line 39, in reraise
    raise value
  File "G:\flaskProject\venv\lib\site-packages\flask\app.py", line 1950, in full_dispatch_request
    rv = self.dispatch_request()
  File "G:\flaskProject\venv\lib\site-packages\flask\app.py", line 1936, in dispatch_request
    return self.view_functions[rule.endpoint](**req.view_args)
  File "G:\flaskProject\apps\routes.py", line 346, in update_cart
    quantity = int(request.form.get('update_num'))
TypeError: int() argument must be a string, a bytes-like object or a number, not 'NoneType'
2021-12-08 12:00:38 INFO routes.py home[line:15] Enter the home page
2021-12-08 12:00:38 INFO routes.py home[line:15] Enter the home page
2021-12-08 12:00:46 ERROR app.py log_exception[line:1891] Exception on /cart/update/19 [POST]
Traceback (most recent call last):
  File "G:\flaskProject\venv\lib\site-packages\flask\app.py", line 2447, in wsgi_app
    response = self.full_dispatch_request()
  File "G:\flaskProject\venv\lib\site-packages\flask\app.py", line 1952, in full_dispatch_request
    rv = self.handle_user_exception(e)
  File "G:\flaskProject\venv\lib\site-packages\flask\app.py", line 1821, in handle_user_exception
    reraise(exc_type, exc_value, tb)
  File "G:\flaskProject\venv\lib\site-packages\flask\_compat.py", line 39, in reraise
    raise value
  File "G:\flaskProject\venv\lib\site-packages\flask\app.py", line 1950, in full_dispatch_request
    rv = self.dispatch_request()
  File "G:\flaskProject\venv\lib\site-packages\flask\app.py", line 1936, in dispatch_request
    return self.view_functions[rule.endpoint](**req.view_args)
  File "G:\flaskProject\apps\routes.py", line 348, in update_cart
    cart_item.quantity = quantity
AttributeError: 'NoneType' object has no attribute 'quantity'
2021-12-08 12:00:58 ERROR app.py log_exception[line:1891] Exception on /cart/update/19 [POST]
Traceback (most recent call last):
  File "G:\flaskProject\venv\lib\site-packages\flask\app.py", line 2447, in wsgi_app
    response = self.full_dispatch_request()
  File "G:\flaskProject\venv\lib\site-packages\flask\app.py", line 1952, in full_dispatch_request
    rv = self.handle_user_exception(e)
  File "G:\flaskProject\venv\lib\site-packages\flask\app.py", line 1821, in handle_user_exception
    reraise(exc_type, exc_value, tb)
  File "G:\flaskProject\venv\lib\site-packages\flask\_compat.py", line 39, in reraise
    raise value
  File "G:\flaskProject\venv\lib\site-packages\flask\app.py", line 1950, in full_dispatch_request
    rv = self.dispatch_request()
  File "G:\flaskProject\venv\lib\site-packages\flask\app.py", line 1936, in dispatch_request
    return self.view_functions[rule.endpoint](**req.view_args)
  File "G:\flaskProject\apps\routes.py", line 348, in update_cart
    cart_item.quantity = quantity
AttributeError: 'NoneType' object has no attribute 'quantity'
2021-12-08 12:03:24 INFO routes.py category[line:106] category items
2021-12-08 12:03:26 INFO routes.py product[line:123] Successfully query
2021-12-08 12:03:26 INFO routes.py product[line:128] Successfully query
2021-12-08 12:03:29 INFO routes.py product[line:123] Successfully query
2021-12-08 12:03:29 INFO routes.py product[line:128] Successfully query
2021-12-08 12:03:30 INFO routes.py product[line:133] Costumer add products
2021-12-08 12:03:30 INFO routes.py product[line:150] Adding to shopping cart successfully
2021-12-08 12:03:38 ERROR app.py log_exception[line:1891] Exception on /cart/update/19 [POST]
Traceback (most recent call last):
  File "G:\flaskProject\venv\lib\site-packages\flask\app.py", line 2447, in wsgi_app
    response = self.full_dispatch_request()
  File "G:\flaskProject\venv\lib\site-packages\flask\app.py", line 1952, in full_dispatch_request
    rv = self.handle_user_exception(e)
  File "G:\flaskProject\venv\lib\site-packages\flask\app.py", line 1821, in handle_user_exception
    reraise(exc_type, exc_value, tb)
  File "G:\flaskProject\venv\lib\site-packages\flask\_compat.py", line 39, in reraise
    raise value
  File "G:\flaskProject\venv\lib\site-packages\flask\app.py", line 1950, in full_dispatch_request
    rv = self.dispatch_request()
  File "G:\flaskProject\venv\lib\site-packages\flask\app.py", line 1936, in dispatch_request
    return self.view_functions[rule.endpoint](**req.view_args)
  File "G:\flaskProject\apps\routes.py", line 348, in update_cart
    cart_item.quantity = quantity
AttributeError: 'NoneType' object has no attribute 'quantity'
2021-12-08 12:06:26 INFO routes.py home[line:15] Enter the home page
2021-12-08 12:06:26 INFO routes.py home[line:15] Enter the home page
2021-12-08 12:07:14 INFO routes.py home[line:15] Enter the home page
2021-12-08 12:07:14 INFO routes.py home[line:15] Enter the home page
2021-12-08 12:07:30 ERROR app.py log_exception[line:1891] Exception on /cart/update/19 [POST]
Traceback (most recent call last):
  File "G:\flaskProject\venv\lib\site-packages\flask\app.py", line 2447, in wsgi_app
    response = self.full_dispatch_request()
  File "G:\flaskProject\venv\lib\site-packages\flask\app.py", line 1952, in full_dispatch_request
    rv = self.handle_user_exception(e)
  File "G:\flaskProject\venv\lib\site-packages\flask\app.py", line 1821, in handle_user_exception
    reraise(exc_type, exc_value, tb)
  File "G:\flaskProject\venv\lib\site-packages\flask\_compat.py", line 39, in reraise
    raise value
  File "G:\flaskProject\venv\lib\site-packages\flask\app.py", line 1950, in full_dispatch_request
    rv = self.dispatch_request()
  File "G:\flaskProject\venv\lib\site-packages\flask\app.py", line 1936, in dispatch_request
    return self.view_functions[rule.endpoint](**req.view_args)
  File "G:\flaskProject\apps\routes.py", line 348, in update_cart
    cart_item.quantity += quantity
TypeError: unsupported operand type(s) for +=: 'int' and 'str'
2021-12-08 12:07:30 ERROR app.py log_exception[line:1891] Exception on /cart/update/19 [POST]
Traceback (most recent call last):
  File "G:\flaskProject\venv\lib\site-packages\flask\app.py", line 2447, in wsgi_app
    response = self.full_dispatch_request()
  File "G:\flaskProject\venv\lib\site-packages\flask\app.py", line 1952, in full_dispatch_request
    rv = self.handle_user_exception(e)
  File "G:\flaskProject\venv\lib\site-packages\flask\app.py", line 1821, in handle_user_exception
    reraise(exc_type, exc_value, tb)
  File "G:\flaskProject\venv\lib\site-packages\flask\_compat.py", line 39, in reraise
    raise value
  File "G:\flaskProject\venv\lib\site-packages\flask\app.py", line 1950, in full_dispatch_request
    rv = self.dispatch_request()
  File "G:\flaskProject\venv\lib\site-packages\flask\app.py", line 1936, in dispatch_request
    return self.view_functions[rule.endpoint](**req.view_args)
  File "G:\flaskProject\apps\routes.py", line 348, in update_cart
    cart_item.quantity += quantity
TypeError: unsupported operand type(s) for +=: 'int' and 'str'
2021-12-08 12:08:09 INFO routes.py home[line:15] Enter the home page
2021-12-08 12:08:09 INFO routes.py home[line:15] Enter the home page
2021-12-08 12:09:25 INFO routes.py home[line:15] Enter the home page
2021-12-08 12:10:03 INFO routes.py home[line:15] Enter the home page
2021-12-08 12:11:21 INFO routes.py home[line:15] Enter the home page
2021-12-08 12:11:21 INFO routes.py home[line:15] Enter the home page
2021-12-08 12:11:50 INFO routes.py home[line:15] Enter the home page
2021-12-08 12:11:52 INFO routes.py category[line:106] category items
2021-12-08 12:11:55 INFO routes.py product[line:123] Successfully query
2021-12-08 12:11:55 INFO routes.py product[line:128] Successfully query
2021-12-08 12:11:57 INFO routes.py product[line:123] Successfully query
2021-12-08 12:11:57 INFO routes.py product[line:128] Successfully query
2021-12-08 12:11:57 INFO routes.py product[line:133] Costumer add products
2021-12-08 12:11:57 INFO routes.py product[line:143] Successfully added items to cart table
2021-12-08 12:11:57 INFO routes.py product[line:150] Adding to shopping cart successfully
2021-12-08 12:12:18 INFO routes.py checkout[line:267] Successfully added information to info table
2021-12-08 12:12:18 INFO routes.py checkout[line:278] Successfully added product to cart_item table
2021-12-08 12:12:18 INFO routes.py checkout[line:285] Successfully delete product from cart table
2021-12-08 12:12:18 INFO routes.py home[line:15] Enter the home page
2021-12-08 12:12:29 INFO routes.py logout[line:374] logout
2021-12-08 12:12:29 INFO routes.py home[line:15] Enter the home page
2021-12-08 12:12:37 INFO routes.py login[line:61] Seller login
2021-12-08 12:16:46 INFO routes.py seller_add[line:477] seller add the product
2021-12-08 12:17:48 INFO routes.py home[line:15] Enter the home page
2021-12-08 12:17:52 INFO routes.py logout[line:374] logout
2021-12-08 12:17:52 INFO routes.py home[line:15] Enter the home page
2021-12-08 12:18:02 INFO routes.py login[line:61] Seller login
2021-12-08 12:18:28 ERROR app.py log_exception[line:1891] Exception on /seller_edit/31 [POST]
Traceback (most recent call last):
  File "G:\flaskProject\venv\lib\site-packages\flask\app.py", line 2447, in wsgi_app
    response = self.full_dispatch_request()
  File "G:\flaskProject\venv\lib\site-packages\flask\app.py", line 1952, in full_dispatch_request
    rv = self.handle_user_exception(e)
  File "G:\flaskProject\venv\lib\site-packages\flask\app.py", line 1821, in handle_user_exception
    reraise(exc_type, exc_value, tb)
  File "G:\flaskProject\venv\lib\site-packages\flask\_compat.py", line 39, in reraise
    raise value
  File "G:\flaskProject\venv\lib\site-packages\flask\app.py", line 1950, in full_dispatch_request
    rv = self.dispatch_request()
  File "G:\flaskProject\venv\lib\site-packages\flask\app.py", line 1936, in dispatch_request
    return self.view_functions[rule.endpoint](**req.view_args)
  File "G:\flaskProject\apps\routes.py", line 446, in seller_edit
    product.image_file = photos.save(form.photo.data)
  File "G:\flaskProject\venv\lib\site-packages\flask_uploads.py", line 402, in save
    raise TypeError("storage must be a werkzeug.FileStorage")
TypeError: storage must be a werkzeug.FileStorage
2021-12-08 12:23:17 INFO routes.py seller_edit[line:450] seller edit the product
2021-12-08 12:23:17 INFO routes.py seller_edit[line:451] Successful modification of database information
2021-12-08 12:23:25 INFO routes.py seller_edit[line:450] seller edit the product
2021-12-08 12:23:25 INFO routes.py seller_edit[line:451] Successful modification of database information
2021-12-08 12:23:49 INFO routes.py seller_edit[line:450] seller edit the product
2021-12-08 12:23:49 INFO routes.py seller_edit[line:451] Successful modification of database information
2021-12-08 12:23:55 INFO routes.py seller_delete[line:428] seller delete the product
2021-12-08 12:24:11 INFO routes.py seller_add[line:478] seller add the product
2021-12-08 12:24:18 INFO routes.py seller_delete[line:428] seller delete the product
2021-12-08 12:24:38 INFO routes.py home[line:15] Enter the home page
2021-12-08 12:24:43 INFO routes.py logout[line:374] logout
2021-12-08 12:24:43 INFO routes.py home[line:15] Enter the home page
2021-12-08 12:24:50 INFO routes.py home[line:15] Enter the home page
2021-12-08 12:24:59 INFO routes.py home[line:15] Enter the home page
